out <Response [200]>
out <Response [200]>
out <Response [200]>
Traceback (most recent call last):
  File "/home/gecs/.local/lib/python3.6/site-packages/urllib3/connection.py", line 159, in _new_conn
    (self._dns_host, self.port), self.timeout, **extra_kw)
  File "/home/gecs/.local/lib/python3.6/site-packages/urllib3/util/connection.py", line 80, in create_connection
    raise err
  File "/home/gecs/.local/lib/python3.6/site-packages/urllib3/util/connection.py", line 70, in create_connection
    sock.connect(sa)
ConnectionRefusedError: [Errno 111] Connection refused

During handling of the above exception, another exception occurred:

Traceback (most recent call last):
  File "/home/gecs/.local/lib/python3.6/site-packages/urllib3/connectionpool.py", line 600, in urlopen
    chunked=chunked)
  File "/home/gecs/.local/lib/python3.6/site-packages/urllib3/connectionpool.py", line 354, in _make_request
    conn.request(method, url, **httplib_request_kw)
  File "/home/gecs/anaconda3/envs/ind_knn_ad/lib/python3.6/http/client.py", line 1287, in request
    self._send_request(method, url, body, headers, encode_chunked)
  File "/home/gecs/anaconda3/envs/ind_knn_ad/lib/python3.6/http/client.py", line 1333, in _send_request
    self.endheaders(body, encode_chunked=encode_chunked)
  File "/home/gecs/anaconda3/envs/ind_knn_ad/lib/python3.6/http/client.py", line 1282, in endheaders
    self._send_output(message_body, encode_chunked=encode_chunked)
  File "/home/gecs/anaconda3/envs/ind_knn_ad/lib/python3.6/http/client.py", line 1042, in _send_output
    self.send(msg)
  File "/home/gecs/anaconda3/envs/ind_knn_ad/lib/python3.6/http/client.py", line 980, in send
    self.connect()
  File "/home/gecs/.local/lib/python3.6/site-packages/urllib3/connection.py", line 181, in connect
    conn = self._new_conn()
  File "/home/gecs/.local/lib/python3.6/site-packages/urllib3/connection.py", line 168, in _new_conn
    self, "Failed to establish a new connection: %s" % e)
urllib3.exceptions.NewConnectionError: <urllib3.connection.HTTPConnection object at 0x7f856fae0da0>: Failed to establish a new connection: [Errno 111] Connection refused

During handling of the above exception, another exception occurred:

Traceback (most recent call last):
  File "/home/gecs/.local/lib/python3.6/site-packages/requests/adapters.py", line 449, in send
    timeout=timeout
  File "/home/gecs/.local/lib/python3.6/site-packages/urllib3/connectionpool.py", line 638, in urlopen
    _stacktrace=sys.exc_info()[2])
  File "/home/gecs/.local/lib/python3.6/site-packages/urllib3/util/retry.py", line 399, in increment
    raise MaxRetryError(_pool, url, error or ResponseError(cause))
urllib3.exceptions.MaxRetryError: HTTPConnectionPool(host='127.0.0.1', port=8203): Max retries exceeded with url: /restore (Caused by NewConnectionError('<urllib3.connection.HTTPConnection object at 0x7f856fae0da0>: Failed to establish a new connection: [Errno 111] Connection refused',))

During handling of the above exception, another exception occurred:

Traceback (most recent call last):
  File "indad/server.py", line 238, in <module>
    admm.restore()
  File "indad/server.py", line 147, in restore
    self.run_each_adm(lambda adm: adm.restore())
  File "indad/server.py", line 160, in run_each_adm
    callback(adm)
  File "indad/server.py", line 147, in <lambda>
    self.run_each_adm(lambda adm: adm.restore())
  File "indad/server.py", line 108, in restore
    out = requests.post(self.hostname + '/restore')
  File "/home/gecs/.local/lib/python3.6/site-packages/requests/api.py", line 116, in post
    return request('post', url, data=data, json=json, **kwargs)
  File "/home/gecs/.local/lib/python3.6/site-packages/requests/api.py", line 60, in request
    return session.request(method=method, url=url, **kwargs)
  File "/home/gecs/.local/lib/python3.6/site-packages/requests/sessions.py", line 533, in request
    resp = self.send(prep, **send_kwargs)
  File "/home/gecs/.local/lib/python3.6/site-packages/requests/sessions.py", line 646, in send
    r = adapter.send(request, **kwargs)
  File "/home/gecs/.local/lib/python3.6/site-packages/requests/adapters.py", line 516, in send
    raise ConnectionError(e, request=request)
requests.exceptions.ConnectionError: HTTPConnectionPool(host='127.0.0.1', port=8203): Max retries exceeded with url: /restore (Caused by NewConnectionError('<urllib3.connection.HTTPConnection object at 0x7f856fae0da0>: Failed to establish a new connection: [Errno 111] Connection refused',))